2022-07-07 23:58:27,156 ERROR: Exception on / [GET] [in C:\Users\zayaz\AppData\Local\Programs\Python\Python310\lib\site-packages\flask\app.py:1455]
Traceback (most recent call last):
  File "C:\Users\zayaz\AppData\Local\Programs\Python\Python310\lib\site-packages\flask\app.py", line 1523, in full_dispatch_request
    rv = self.dispatch_request()
  File "C:\Users\zayaz\AppData\Local\Programs\Python\Python310\lib\site-packages\flask\app.py", line 1499, in dispatch_request
    self.raise_routing_exception(req)
  File "C:\Users\zayaz\AppData\Local\Programs\Python\Python310\lib\site-packages\flask\app.py", line 1481, in raise_routing_exception
    raise request.routing_exception  # type: ignore
  File "C:\Users\zayaz\AppData\Local\Programs\Python\Python310\lib\site-packages\flask\ctx.py", line 397, in match_request
    result = self.url_adapter.match(return_rule=True)  # type: ignore
  File "C:\Users\zayaz\AppData\Local\Programs\Python\Python310\lib\site-packages\werkzeug\routing.py", line 2047, in match
    raise NotFound()
werkzeug.exceptions.NotFound: 404 Not Found: The requested URL was not found on the server. If you entered the URL manually please check your spelling and try again.

During handling of the above exception, another exception occurred:

Traceback (most recent call last):
  File "C:\Users\zayaz\AppData\Local\Programs\Python\Python310\lib\site-packages\sqlalchemy\engine\base.py", line 1819, in _execute_context
    self.dialect.do_execute(
  File "C:\Users\zayaz\AppData\Local\Programs\Python\Python310\lib\site-packages\sqlalchemy\engine\default.py", line 732, in do_execute
    cursor.execute(statement, parameters)
sqlite3.OperationalError: no such table: user

The above exception was the direct cause of the following exception:

Traceback (most recent call last):
  File "C:\Users\zayaz\AppData\Local\Programs\Python\Python310\lib\site-packages\flask\app.py", line 2077, in wsgi_app
    response = self.full_dispatch_request()
  File "C:\Users\zayaz\AppData\Local\Programs\Python\Python310\lib\site-packages\flask\app.py", line 1525, in full_dispatch_request
    rv = self.handle_user_exception(e)
  File "C:\Users\zayaz\AppData\Local\Programs\Python\Python310\lib\site-packages\flask\app.py", line 1384, in handle_user_exception
    return self.handle_http_exception(e)
  File "C:\Users\zayaz\AppData\Local\Programs\Python\Python310\lib\site-packages\flask\app.py", line 1324, in handle_http_exception
    return self.ensure_sync(handler)(e)
  File "C:\Users\zayaz\PycharmProjects\Customer-service\app\errors\handlers.py", line 14, in not_found_error
    return render_template('errors/404.html'), 404
  File "C:\Users\zayaz\AppData\Local\Programs\Python\Python310\lib\site-packages\flask\templating.py", line 147, in render_template
    ctx.app.update_template_context(context)
  File "C:\Users\zayaz\AppData\Local\Programs\Python\Python310\lib\site-packages\flask\app.py", line 756, in update_template_context
    context.update(func())
  File "C:\Users\zayaz\AppData\Local\Programs\Python\Python310\lib\site-packages\flask_login\utils.py", line 417, in _user_context_processor
    return dict(current_user=_get_user())
  File "C:\Users\zayaz\AppData\Local\Programs\Python\Python310\lib\site-packages\flask_login\utils.py", line 384, in _get_user
    current_app.login_manager._load_user()
  File "C:\Users\zayaz\AppData\Local\Programs\Python\Python310\lib\site-packages\flask_login\login_manager.py", line 355, in _load_user
    user = self._user_callback(user_id)
  File "C:\Users\zayaz\PycharmProjects\Customer-service\app\models.py", line 57, in load_user
    return User.query.get(int(id))
  File "<string>", line 2, in get
  File "C:\Users\zayaz\AppData\Local\Programs\Python\Python310\lib\site-packages\sqlalchemy\util\deprecations.py", line 401, in warned
    return fn(*args, **kwargs)
  File "C:\Users\zayaz\AppData\Local\Programs\Python\Python310\lib\site-packages\sqlalchemy\orm\query.py", line 943, in get
    return self._get_impl(ident, loading.load_on_pk_identity)
  File "C:\Users\zayaz\AppData\Local\Programs\Python\Python310\lib\site-packages\sqlalchemy\orm\query.py", line 947, in _get_impl
    return self.session._get_impl(
  File "C:\Users\zayaz\AppData\Local\Programs\Python\Python310\lib\site-packages\sqlalchemy\orm\session.py", line 2896, in _get_impl
    return db_load_fn(
  File "C:\Users\zayaz\AppData\Local\Programs\Python\Python310\lib\site-packages\sqlalchemy\orm\loading.py", line 530, in load_on_pk_identity
    session.execute(
  File "C:\Users\zayaz\AppData\Local\Programs\Python\Python310\lib\site-packages\sqlalchemy\orm\session.py", line 1696, in execute
    result = conn._execute_20(statement, params or {}, execution_options)
  File "C:\Users\zayaz\AppData\Local\Programs\Python\Python310\lib\site-packages\sqlalchemy\engine\base.py", line 1631, in _execute_20
    return meth(self, args_10style, kwargs_10style, execution_options)
  File "C:\Users\zayaz\AppData\Local\Programs\Python\Python310\lib\site-packages\sqlalchemy\sql\elements.py", line 325, in _execute_on_connection
    return connection._execute_clauseelement(
  File "C:\Users\zayaz\AppData\Local\Programs\Python\Python310\lib\site-packages\sqlalchemy\engine\base.py", line 1498, in _execute_clauseelement
    ret = self._execute_context(
  File "C:\Users\zayaz\AppData\Local\Programs\Python\Python310\lib\site-packages\sqlalchemy\engine\base.py", line 1862, in _execute_context
    self._handle_dbapi_exception(
  File "C:\Users\zayaz\AppData\Local\Programs\Python\Python310\lib\site-packages\sqlalchemy\engine\base.py", line 2043, in _handle_dbapi_exception
    util.raise_(
  File "C:\Users\zayaz\AppData\Local\Programs\Python\Python310\lib\site-packages\sqlalchemy\util\compat.py", line 207, in raise_
    raise exception
  File "C:\Users\zayaz\AppData\Local\Programs\Python\Python310\lib\site-packages\sqlalchemy\engine\base.py", line 1819, in _execute_context
    self.dialect.do_execute(
  File "C:\Users\zayaz\AppData\Local\Programs\Python\Python310\lib\site-packages\sqlalchemy\engine\default.py", line 732, in do_execute
    cursor.execute(statement, parameters)
sqlalchemy.exc.OperationalError: (sqlite3.OperationalError) no such table: user
[SQL: SELECT user.id AS user_id, user.username AS user_username, user.phone_number AS user_phone_number, user.password_hash AS user_password_hash, user.last_seen AS user_last_seen 
FROM user 
WHERE user.id = ?]
[parameters: (1,)]
(Background on this error at: https://sqlalche.me/e/14/e3q8)
2022-07-08 00:04:24,109 INFO: All good [in C:\Users\zayaz\PycharmProjects\Customer-service\app\__init__.py:85]
2022-07-08 00:04:26,656 INFO: All good [in C:\Users\zayaz\PycharmProjects\Customer-service\app\__init__.py:85]
2022-07-08 00:05:45,471 INFO: All good [in C:\Users\zayaz\PycharmProjects\Customer-service\app\__init__.py:85]
2022-07-08 00:05:48,222 INFO: All good [in C:\Users\zayaz\PycharmProjects\Customer-service\app\__init__.py:85]
2022-07-08 00:16:34,948 INFO: All good [in C:\Users\zayaz\PycharmProjects\Customer-service\app\__init__.py:85]
