2022-06-20 23:19:44,550 ERROR: Exception on /user/VadimM [GET] [in C:\Users\zayaz\PycharmProjects\Customer-service\venv\lib\site-packages\flask\app.py:1455]
Traceback (most recent call last):
  File "C:\Users\zayaz\PycharmProjects\Customer-service\venv\lib\site-packages\flask\app.py", line 2077, in wsgi_app
    response = self.full_dispatch_request()
  File "C:\Users\zayaz\PycharmProjects\Customer-service\venv\lib\site-packages\flask\app.py", line 1525, in full_dispatch_request
    rv = self.handle_user_exception(e)
  File "C:\Users\zayaz\PycharmProjects\Customer-service\venv\lib\site-packages\flask\app.py", line 1523, in full_dispatch_request
    rv = self.dispatch_request()
  File "C:\Users\zayaz\PycharmProjects\Customer-service\venv\lib\site-packages\flask\app.py", line 1509, in dispatch_request
    return self.ensure_sync(self.view_functions[rule.endpoint])(**req.view_args)
  File "C:\Users\zayaz\PycharmProjects\Customer-service\venv\lib\site-packages\flask_login\utils.py", line 303, in decorated_view
    return current_app.ensure_sync(func)(*args, **kwargs)
  File "C:\Users\zayaz\PycharmProjects\Customer-service\app\routes.py", line 109, in user
    services=services, date=date)
NameError: name 'services' is not defined
2022-06-20 23:26:51,103 INFO: All good [in C:\Users\zayaz\PycharmProjects\Customer-service\app\errors.py:48]
2022-06-20 23:27:05,479 ERROR: Exception on /user/VadimM [GET] [in C:\Users\zayaz\PycharmProjects\Customer-service\venv\lib\site-packages\flask\app.py:1455]
Traceback (most recent call last):
  File "C:\Users\zayaz\PycharmProjects\Customer-service\venv\lib\site-packages\flask\app.py", line 2077, in wsgi_app
    response = self.full_dispatch_request()
  File "C:\Users\zayaz\PycharmProjects\Customer-service\venv\lib\site-packages\flask\app.py", line 1525, in full_dispatch_request
    rv = self.handle_user_exception(e)
  File "C:\Users\zayaz\PycharmProjects\Customer-service\venv\lib\site-packages\flask\app.py", line 1523, in full_dispatch_request
    rv = self.dispatch_request()
  File "C:\Users\zayaz\PycharmProjects\Customer-service\venv\lib\site-packages\flask\app.py", line 1509, in dispatch_request
    return self.ensure_sync(self.view_functions[rule.endpoint])(**req.view_args)
  File "C:\Users\zayaz\PycharmProjects\Customer-service\venv\lib\site-packages\flask_login\utils.py", line 303, in decorated_view
    return current_app.ensure_sync(func)(*args, **kwargs)
  File "C:\Users\zayaz\PycharmProjects\Customer-service\app\routes.py", line 109, in user
    services=services, date=date)
NameError: name 'services' is not defined
2022-06-20 23:36:18,155 INFO: All good [in C:\Users\zayaz\PycharmProjects\Customer-service\app\errors.py:49]
2022-06-20 23:36:46,312 ERROR: Exception on /user/VadimM [GET] [in C:\Users\zayaz\PycharmProjects\Customer-service\venv\lib\site-packages\flask\app.py:1455]
Traceback (most recent call last):
  File "C:\Users\zayaz\PycharmProjects\Customer-service\venv\lib\site-packages\flask\app.py", line 2077, in wsgi_app
    response = self.full_dispatch_request()
  File "C:\Users\zayaz\PycharmProjects\Customer-service\venv\lib\site-packages\flask\app.py", line 1525, in full_dispatch_request
    rv = self.handle_user_exception(e)
  File "C:\Users\zayaz\PycharmProjects\Customer-service\venv\lib\site-packages\flask\app.py", line 1523, in full_dispatch_request
    rv = self.dispatch_request()
  File "C:\Users\zayaz\PycharmProjects\Customer-service\venv\lib\site-packages\flask\app.py", line 1509, in dispatch_request
    return self.ensure_sync(self.view_functions[rule.endpoint])(**req.view_args)
  File "C:\Users\zayaz\PycharmProjects\Customer-service\venv\lib\site-packages\flask_login\utils.py", line 303, in decorated_view
    return current_app.ensure_sync(func)(*args, **kwargs)
  File "C:\Users\zayaz\PycharmProjects\Customer-service\app\routes.py", line 109, in user
    services=services, date=date)
NameError: name 'services' is not defined
2022-06-20 23:39:43,021 INFO: All good [in C:\Users\zayaz\PycharmProjects\Customer-service\app\errors.py:45]
2022-06-20 23:40:45,941 INFO: All good [in C:\Users\zayaz\PycharmProjects\Customer-service\app\errors.py:45]
2022-06-20 23:41:17,136 INFO: All good [in C:\Users\zayaz\PycharmProjects\Customer-service\app\errors.py:45]
2022-06-20 23:41:24,976 ERROR: Exception on /user/VadimM [GET] [in C:\Users\zayaz\PycharmProjects\Customer-service\venv\lib\site-packages\flask\app.py:1455]
Traceback (most recent call last):
  File "C:\Users\zayaz\PycharmProjects\Customer-service\venv\lib\site-packages\flask\app.py", line 2077, in wsgi_app
    response = self.full_dispatch_request()
  File "C:\Users\zayaz\PycharmProjects\Customer-service\venv\lib\site-packages\flask\app.py", line 1525, in full_dispatch_request
    rv = self.handle_user_exception(e)
  File "C:\Users\zayaz\PycharmProjects\Customer-service\venv\lib\site-packages\flask\app.py", line 1523, in full_dispatch_request
    rv = self.dispatch_request()
  File "C:\Users\zayaz\PycharmProjects\Customer-service\venv\lib\site-packages\flask\app.py", line 1509, in dispatch_request
    return self.ensure_sync(self.view_functions[rule.endpoint])(**req.view_args)
  File "C:\Users\zayaz\PycharmProjects\Customer-service\venv\lib\site-packages\flask_login\utils.py", line 303, in decorated_view
    return current_app.ensure_sync(func)(*args, **kwargs)
  File "C:\Users\zayaz\PycharmProjects\Customer-service\app\routes.py", line 109, in user
    services=services, date=date)
NameError: name 'services' is not defined
2022-06-20 23:44:11,083 INFO: All good [in C:\Users\zayaz\PycharmProjects\Customer-service\app\errors.py:46]
2022-06-20 23:47:13,079 INFO: All good [in C:\Users\zayaz\PycharmProjects\Customer-service\app\errors.py:46]
2022-06-20 23:48:53,953 INFO: All good [in C:\Users\zayaz\PycharmProjects\Customer-service\app\errors.py:46]
2022-06-20 23:49:45,435 ERROR: Exception on /user/VadimM [GET] [in C:\Users\zayaz\PycharmProjects\Customer-service\venv\lib\site-packages\flask\app.py:1455]
Traceback (most recent call last):
  File "C:\Users\zayaz\PycharmProjects\Customer-service\venv\lib\site-packages\flask\app.py", line 2077, in wsgi_app
    response = self.full_dispatch_request()
  File "C:\Users\zayaz\PycharmProjects\Customer-service\venv\lib\site-packages\flask\app.py", line 1525, in full_dispatch_request
    rv = self.handle_user_exception(e)
  File "C:\Users\zayaz\PycharmProjects\Customer-service\venv\lib\site-packages\flask\app.py", line 1523, in full_dispatch_request
    rv = self.dispatch_request()
  File "C:\Users\zayaz\PycharmProjects\Customer-service\venv\lib\site-packages\flask\app.py", line 1509, in dispatch_request
    return self.ensure_sync(self.view_functions[rule.endpoint])(**req.view_args)
  File "C:\Users\zayaz\PycharmProjects\Customer-service\venv\lib\site-packages\flask_login\utils.py", line 303, in decorated_view
    return current_app.ensure_sync(func)(*args, **kwargs)
  File "C:\Users\zayaz\PycharmProjects\Customer-service\app\routes.py", line 109, in user
    services=services, date=date)
NameError: name 'services' is not defined
2022-06-20 23:50:29,869 INFO: All good [in C:\Users\zayaz\PycharmProjects\Customer-service\app\errors.py:46]
2022-06-20 23:51:57,348 INFO: All good [in C:\Users\zayaz\PycharmProjects\Customer-service\app\errors.py:46]
2022-06-20 23:53:02,182 INFO: All good [in C:\Users\zayaz\PycharmProjects\Customer-service\app\errors.py:47]
2022-06-20 23:53:42,046 INFO: All good [in C:\Users\zayaz\PycharmProjects\Customer-service\app\errors.py:47]
2022-06-20 23:54:58,814 INFO: All good [in C:\Users\zayaz\PycharmProjects\Customer-service\app\errors.py:47]
2022-06-21 00:01:15,537 INFO: All good [in C:\Users\zayaz\PycharmProjects\Customer-service\app\errors.py:45]
2022-06-21 00:01:20,539 ERROR: Exception on /user/VadimM [GET] [in C:\Users\zayaz\PycharmProjects\Customer-service\venv\lib\site-packages\flask\app.py:1455]
Traceback (most recent call last):
  File "C:\Users\zayaz\PycharmProjects\Customer-service\venv\lib\site-packages\flask\app.py", line 2077, in wsgi_app
    response = self.full_dispatch_request()
  File "C:\Users\zayaz\PycharmProjects\Customer-service\venv\lib\site-packages\flask\app.py", line 1525, in full_dispatch_request
    rv = self.handle_user_exception(e)
  File "C:\Users\zayaz\PycharmProjects\Customer-service\venv\lib\site-packages\flask\app.py", line 1523, in full_dispatch_request
    rv = self.dispatch_request()
  File "C:\Users\zayaz\PycharmProjects\Customer-service\venv\lib\site-packages\flask\app.py", line 1509, in dispatch_request
    return self.ensure_sync(self.view_functions[rule.endpoint])(**req.view_args)
  File "C:\Users\zayaz\PycharmProjects\Customer-service\venv\lib\site-packages\flask_login\utils.py", line 303, in decorated_view
    return current_app.ensure_sync(func)(*args, **kwargs)
  File "C:\Users\zayaz\PycharmProjects\Customer-service\app\routes.py", line 109, in user
    services=services, date=date)
NameError: name 'services' is not defined
2022-06-21 00:03:11,418 INFO: All good [in C:\Users\zayaz\PycharmProjects\Customer-service\app\errors.py:45]
2022-06-21 00:03:59,812 INFO: All good [in C:\Users\zayaz\PycharmProjects\Customer-service\app\errors.py:45]
2022-06-21 00:05:56,500 INFO: All good [in C:\Users\zayaz\PycharmProjects\Customer-service\app\errors.py:45]
2022-06-21 00:05:58,484 INFO: All good [in C:\Users\zayaz\PycharmProjects\Customer-service\app\errors.py:45]
2022-06-21 00:06:11,964 INFO: All good [in C:\Users\zayaz\PycharmProjects\Customer-service\app\errors.py:45]
2022-06-21 00:06:14,072 INFO: All good [in C:\Users\zayaz\PycharmProjects\Customer-service\app\errors.py:45]
2022-06-21 00:11:33,444 INFO: All good [in C:\Users\zayaz\PycharmProjects\Customer-service\app\errors.py:46]
